[[
  {
    "name": "flask.request",
    "service": "flask",
    "resource": "GET /error",
    "trace_id": 0,
    "span_id": 1,
    "parent_id": 0,
    "type": "web",
    "error": 1,
    "meta": {
      "_dd.p.dm": "-0",
      "flask.endpoint": "endpoint_error",
      "flask.url_rule": "/error",
      "flask.version": "0.12.5",
      "http.method": "GET",
      "http.status_code": "500",
      "http.url": "http://localhost/error",
      "runtime-id": "4d7f526a178146eaacd40c2d536aacaa"
    },
    "metrics": {
      "_dd.agent_psr": 1.0,
      "_dd.measured": 1,
      "_dd.top_level": 1,
      "_dd.tracer_kr": 1.0,
      "_sampling_priority_v1": 1,
      "system.pid": 36411
    },
    "duration": 3319000,
    "start": 1657053444129767000
  },
     {
       "name": "flask.try_trigger_before_first_request_functions",
       "service": "flask",
       "resource": "flask.try_trigger_before_first_request_functions",
       "trace_id": 0,
       "span_id": 2,
       "parent_id": 1,
       "duration": 19000,
       "start": 1657053444130141000
     },
     {
       "name": "flask.preprocess_request",
       "service": "flask",
       "resource": "flask.preprocess_request",
       "trace_id": 0,
       "span_id": 3,
       "parent_id": 1,
       "duration": 16000,
       "start": 1657053444130218000
     },
     {
       "name": "flask.dispatch_request",
       "service": "flask",
       "resource": "flask.dispatch_request",
       "trace_id": 0,
       "span_id": 4,
       "parent_id": 1,
       "error": 1,
       "meta": {
         "error.msg": "custom error message",
         "error.stack": "Traceback (most recent call last):\n  File \"/Users/munir.abdinur/Documents/ApmPython/dd-trace-py/ddtrace/contrib/flask/patch.py\", line 481, in _traced_request\n    return wrapped(*args, **kwargs)\n  File \"/Users/munir.abdinur/Documents/ApmPython/dd-trace-py/.riot/venv_py3615_flask~0120_pytest~30_more_itertools8110_itsdangerous20_markupsafe20/lib/python3.6/site-packages/flask/app.py\", line 1598, in dispatch_request\n    return self.view_functions[rule.endpoint](**req.view_args)\n  File \"/Users/munir.abdinur/Documents/ApmPython/dd-trace-py/ddtrace/contrib/flask/wrappers.py\", line 25, in trace_func\n    return wrapped(*args, **kwargs)\n  File \"/Users/munir.abdinur/Documents/ApmPython/dd-trace-py/tests/contrib/flask/test_errorhandler.py\", line 75, in endpoint_error\n    raise FlaskTestException(\"custom error message\")\ntests.contrib.flask.test_errorhandler.FlaskErrorhandlerTestCase.test_raise_user_exception.<locals>.FlaskTestException: custom error message\n",
         "error.type": "tests.contrib.flask.test_errorhandler.FlaskTestException"
       },
       "duration": 546000,
       "start": 1657053444130267000
     },
        {
          "name": "tests.contrib.flask.test_errorhandler.endpoint_error",
          "service": "flask",
          "resource": "/error",
          "trace_id": 0,
          "span_id": 9,
          "parent_id": 4,
          "error": 1,
          "meta": {
            "error.msg": "custom error message",
            "error.stack": "Traceback (most recent call last):\n  File \"/Users/munir.abdinur/Documents/ApmPython/dd-trace-py/ddtrace/contrib/flask/wrappers.py\", line 25, in trace_func\n    return wrapped(*args, **kwargs)\n  File \"/Users/munir.abdinur/Documents/ApmPython/dd-trace-py/tests/contrib/flask/test_errorhandler.py\", line 75, in endpoint_error\n    raise FlaskTestException(\"custom error message\")\ntests.contrib.flask.test_errorhandler.FlaskErrorhandlerTestCase.test_raise_user_exception.<locals>.FlaskTestException: custom error message\n",
            "error.type": "tests.contrib.flask.test_errorhandler.FlaskTestException"
          },
          "duration": 193000,
          "start": 1657053444130493000
        },
     {
       "name": "flask.handle_user_exception",
       "service": "flask",
       "resource": "flask.handle_user_exception",
       "trace_id": 0,
       "span_id": 5,
       "parent_id": 1,
       "error": 1,
       "meta": {
         "error.msg": "custom error message",
         "error.stack": "Traceback (most recent call last):\n  File \"/Users/munir.abdinur/Documents/ApmPython/dd-trace-py/ddtrace/contrib/flask/helpers.py\", line 36, in wrapper\n    return wrapped(*args, **kwargs)\n  File \"/Users/munir.abdinur/Documents/ApmPython/dd-trace-py/.riot/venv_py3615_flask~0120_pytest~30_more_itertools8110_itsdangerous20_markupsafe20/lib/python3.6/site-packages/flask/app.py\", line 1517, in handle_user_exception\n    reraise(exc_type, exc_value, tb)\n  File \"/Users/munir.abdinur/Documents/ApmPython/dd-trace-py/.riot/venv_py3615_flask~0120_pytest~30_more_itertools8110_itsdangerous20_markupsafe20/lib/python3.6/site-packages/flask/_compat.py\", line 33, in reraise\n    raise value\n  File \"/Users/munir.abdinur/Documents/ApmPython/dd-trace-py/.riot/venv_py3615_flask~0120_pytest~30_more_itertools8110_itsdangerous20_markupsafe20/lib/python3.6/site-packages/flask/app.py\", line 1612, in full_dispatch_request\n    rv = self.dispatch_request()\n  File \"/Users/munir.abdinur/Documents/ApmPython/dd-trace-py/ddtrace/contrib/flask/helpers.py\", line 25, in wrapper\n    return func(pin, wrapped, instance, args, kwargs)\n  File \"/Users/munir.abdinur/Documents/ApmPython/dd-trace-py/ddtrace/contrib/flask/patch.py\", line 481, in _traced_request\n    return wrapped(*args, **kwargs)\n  File \"/Users/munir.abdinur/Documents/ApmPython/dd-trace-py/.riot/venv_py3615_flask~0120_pytest~30_more_itertools8110_itsdangerous20_markupsafe20/lib/python3.6/site-packages/flask/app.py\", line 1598, in dispatch_request\n    return self.view_functions[rule.endpoint](**req.view_args)\n  File \"/Users/munir.abdinur/Documents/ApmPython/dd-trace-py/ddtrace/contrib/flask/wrappers.py\", line 25, in trace_func\n    return wrapped(*args, **kwargs)\n  File \"/Users/munir.abdinur/Documents/ApmPython/dd-trace-py/tests/contrib/flask/test_errorhandler.py\", line 75, in endpoint_error\n    raise FlaskTestException(\"custom error message\")\ntests.contrib.flask.test_errorhandler.FlaskErrorhandlerTestCase.test_raise_user_exception.<locals>.FlaskTestException: custom error message\n",
         "error.type": "tests.contrib.flask.test_errorhandler.FlaskTestException"
       },
       "duration": 572000,
       "start": 1657053444130877000
     },
     {
       "name": "flask.handle_exception",
       "service": "flask",
       "resource": "flask.handle_exception",
       "trace_id": 0,
       "span_id": 6,
       "parent_id": 1,
       "duration": 1311000,
       "start": 1657053444131493000
     },
     {
       "name": "flask.do_teardown_request",
       "service": "flask",
       "resource": "flask.do_teardown_request",
       "trace_id": 0,
       "span_id": 7,
       "parent_id": 1,
       "duration": 25000,
       "start": 1657053444132991000
     },
     {
       "name": "flask.do_teardown_appcontext",
       "service": "flask",
       "resource": "flask.do_teardown_appcontext",
       "trace_id": 0,
       "span_id": 8,
       "parent_id": 1,
       "duration": 13000,
       "start": 1657053444133058000
     }]]
